Workbook

Sheet Platform review
A1: Platform | B1: Project stage | C1: Project tasks | D1: Source | E1: Keywords
A2: Mendix | B2: Design | D2: https://docs.mendix.com/
A3: =A$2 -> Mendix | B3: =B$2 -> Design | C3: Workflow model | D3: https://docs.mendix.com/refguide/nanoflows/ | E3: +"BPMN Process Model"
A4: =A$2 -> Mendix | B4: =B$2 -> Design | C4: Database model | D4: https://docs.mendix.com/refguide/domain-model/ | E4: "Domain Model", "Data Structure", "Entity Diagrams", "Association", "One-to-Many", "Many-to-Many", "Denormalization", "XPath"
A5: =A$2 -> Mendix | B5: =B$2 -> Design | C5: UI model | D5: https://docs.mendix.com/refguide/pages/ | E5: "Boolean Expressions", "Responsive Web Design", "Data Types"
A6: =A$2 -> Mendix | B6: =B$2 -> Design | C6: Validations | D6: https://docs.mendix.com/refguide/nanoflows/ https://docs.mendix.com/refguide/expressions/ | E6: "Transactions", "JavaScript", "String Functions", "Conditional Expressions", "Arithmetic Expressions", "Boolean Expressions", "Enumerations"
A7: =A$2 -> Mendix | B7: =B$2 -> Design | C7: Application logic | D7: https://docs.mendix.com/refguide/application-logic/ https://docs.mendix.com/refguide/resources/ | E7: "Sequence Flow", "Activity Diagram", "Control Structures", "Algorithms", "Java", "JavaScript", "SQL/OQL", "Regular Expressions", "Variables", "Data Types"
A8: =A$2 -> Mendix | B8: Development
A9: =A$2 -> Mendix | B9: =B$8 -> Development | C9: Workflow design and development | D9: https://docs.mendix.com/refguide/workflows/ https://docs.mendix.com/refguide/workflow-engine/ | E9: +"BPMN Process Model", "Events", "Triggers", "Java API"
A10: =A$2 -> Mendix | B10: =B$8 -> Development | C10: Database design | D10: https://docs.mendix.com/howto/data-models/ | E10: "Denormalization", "Relational Database", "SQL"
A11: =A$2 -> Mendix | B11: =B$8 -> Development | C11: Fetching data | D11: https://www.mendix.com/evaluation-guide/app-capabilities/data-querying-management/ | E11: "Xpath", "OQL", "SQL", "Odata"
A12: =A$2 -> Mendix | B12: =B$8 -> Development | C12: GUI design and development | D12: https://docs.mendix.com/howto/front-end/ | E12: "HTML", "CSS", "SASS (SCSS)", "Themes"
A13: =A$2 -> Mendix | B13: =B$8 -> Development | C13: Data validation development | D13: https://docs.mendix.com/refguide/setting-up-data-validation/ | E13: "Conditional Expressions", "Boolean Expressions", "Domain Model"
A14: =A$2 -> Mendix | B14: =B$8 -> Development | C14: Actions design and development | D14: https://docs.mendix.com/howto/extensibility/build-javascript-actions/ | E14: "Java", "JavaScript", "API"
A15: =A$2 -> Mendix | B15: =B$8 -> Development | C15: Programming | D15: https://docs.mendix.com/refguide/java-programming/ https://docs.mendix.com/refguide/mobile/introduction-to-mobile-technologies/ | E15: "Eclipse", "Java API", "Java", "Emulators Andoid iOS", "PWA", "Native Mobile App"
A16: =A$2 -> Mendix | B16: Implementation
A17: =A$2 -> Mendix | B17: =B$16 -> Implementation | C17: Runtime server installation | D17: https://docs.mendix.com/refguide/runtime-server/ | E17: "File Storage", "Database Synchronization", "REST API", "SOAP", "WSDL", "Swagger", "Relational Database", "Xpath", "OQL", "Java", "API", "HTTPS Server"
A18: =A$2 -> Mendix | B18: =B$16 -> Implementation | C18: Database installation | D18: https://docs.mendix.com/refguide/data-storage/ | E18: "Relational Database", "File Storage"
A19: =A$2 -> Mendix | B19: =B$16 -> Implementation | C19: Client module installation | D19: https://docs.mendix.com/refguide/mendix-client/ | E19: "HTTPS Server", "API"
A20: =A$2 -> Mendix | B20: =B$16 -> Implementation | C20: Deployment | D20: https://docs.mendix.com/developerportal/deploy/ | E20: "Cloud Services", "CI/CD", "Docker", "Kubernetes"
A21: =A$2 -> Mendix | B21: =B$16 -> Implementation | C21: Version control | D21: https://docs.mendix.com/refguide/version-control/ | E21: "Git", "Code Repository Concept"
C22: -
A23: Outsystems | B23: =B$2 -> Design | D23: https://success.outsystems.com/documentation/
A24: =$A$23 -> Outsystems | B24: =B$2 -> Design | C24: Workflow model | D24: https://success.outsystems.com/documentation/11/developing_an_application/use_processes_bpt/processes/ | E24: "Custom Process Model"
A25: =$A$23 -> Outsystems | B25: =B$2 -> Design | C25: Database model | D25: https://success.outsystems.com/documentation/11/developing_an_application/use_data/data_modeling/entity_relationships/ ??? | E25: "Entity Relationships", "Entity Diagrams", "Primary Key", "Foreign Key", "One-to-One", "One-to-Many", "Many-to-Many", "Indexes", "Data Types"
A26: =$A$23 -> Outsystems | B26: =B$2 -> Design | C26: UI model | D26: https://success.outsystems.com/documentation/11/developing_an_application/design_ui/ | E26: +"Screen Templates", "Reactive Web App", +"Business Data Types", "Variables", "Boolean expressions", "Conditional Expressions"
A27: =$A$23 -> Outsystems | B27: =B$2 -> Design | C27: Validations | D27: https://success.outsystems.com/documentation/11/developing_an_application/design_ui/forms/validate_the_fields_of_a_form/ | E27: "Boolean expressions", "Conditional Expressions"
A28: =$A$23 -> Outsystems | B28: =B$2 -> Design | C28: Application logic | D28: https://success.outsystems.com/documentation/11/developing_an_application/implement_application_logic/actions_in_reactive_web_and_mobile_apps/ https://success.outsystems.com/documentation/11/developing_an_application/implement_application_logic/actions_in_web_applications/ | E28: +"Graphical actions", "Variables"
A29: =$A$23 -> Outsystems | B29: =B$8 -> Development
A30: =$A$23 -> Outsystems | B30: =B$8 -> Development | C30: Workflow design and development | D30: https://success.outsystems.com/documentation/11/developing_an_application/use_processes_bpt/ | E30: "Custom Process Model"
A31: =$A$23 -> Outsystems | B31: =B$8 -> Development | C31: Database design | D31: https://success.outsystems.com/documentation/11/developing_an_application/use_data/data_modeling/ | E31: "Relational Database", "SQL"
A32: =$A$23 -> Outsystems | B32: =B$8 -> Development | C32: Fetching data | D32: https://success.outsystems.com/documentation/11/developing_an_application/use_data/query_data/fetch_data_using_human_language/ https://success.outsystems.com/documentation/11/developing_an_application/use_data/query_data/fetch_and_display_data_from_the_database_in_outsystems/ https://success.outsystems.com/documentation/11/developing_an_application/use_data/query_data/sql_queries/ | E32: +"Human Language", +"GUI Queries", "SQL Queries"
A33: =$A$23 -> Outsystems | B33: =B$8 -> Development | C33: GUI design and development | D33: https://success.outsystems.com/documentation/11/developing_an_application/design_ui/ | E33: "CSS", "Grid", "Style Classes", "Responsive Web Design", "IT Data Types", "Responsive Breakpoints", "Reactive Web App", "Event Propagation", "Master Detail", "Programming Functions", "HTML"
A34: =$A$23 -> Outsystems | B34: =B$8 -> Development | C34: Data validation development | D34: https://success.outsystems.com/documentation/11/developing_an_application/design_ui/forms/validate_the_fields_of_a_form/ | E34: "Conditional Expressions", "Boolean Expressions", "Data Fields"
A35: =$A$23 -> Outsystems | B35: =B$8 -> Development | C35: Actions design and development | D35: https://success.outsystems.com/documentation/11/developing_an_application/implement_application_logic/code_mentor_logic_suggestions/ https://success.outsystems.com/documentation/11/reference/outsystems_language/logic/expressions/ | E35: +"AI Assisted Development", "Expressions", "JavaScript", "REST API", "SOAP"
A36: =$A$23 -> Outsystems | B36: =B$8 -> Development | C36: Programming | D36: https://success.outsystems.com/documentation/11/extensibility_and_integration/extend_logic_with_your_own_code/ | E36: ".NET", "+Visual Programming", "HTML DOM", "Iteration Statements", "Conditional Expressions"
A37: =$A$23 -> Outsystems | B37: =B$16 -> Implementation
A38: =$A$23 -> Outsystems | B38: =B$16 -> Implementation | C38: Runtime server installation | D38: https://success.outsystems.com/documentation/11/setup_and_maintain_your_outsystems_infrastructure/setting_up_outsystems/ | E38: "Deployment Controller Service", "Scheduler Service", "Compiler Service", "Log Service", "HTTPS Server", "Shared Libraries", "Load Balancing"
A39: =$A$23 -> Outsystems | B39: =B$16 -> Implementation | C39: Database installation | D39: https://success.outsystems.com/documentation/11/setup_and_maintain_your_outsystems_infrastructure/setting_up_outsystems/default_platform_server_and_database_configurations/ | E39: "Relational Database", "file storage"
A40: =$A$23 -> Outsystems | B40: =B$16 -> Implementation | C40: Client module installation | D40: https://success.outsystems.com/documentation/11/setup_and_maintain_your_outsystems_infrastructure/setting_up_outsystems/ | E40: "Binaries", ".NET Framework"
...

Sheet CLASSIFICATION
A1: Project Stage | B1: Functional scope | C1: Keyword | D1: Classification (Generalized keyword) | E1: Importance | F1: Project Stage Aggr | G1: Functional Scope Aggr | H1: Keyword Aggr | I1: CONC keywords | J1: CONC generalized keywords | K1: CONC generalized keywords and importance
A2: Design | B2: Workflow model | C2: +BPMN Process Model | E2: 5 | F2: {=_xlfn.XLOOKUP(TRUE,A$2:A2<>"",A$2:A2,,,-1)} -> Design | G2: {=_xlfn.XLOOKUP(TRUE,B$2:B2<>"",B$2:B2,,,-1)} -> Workflow model | H2: =IF(CLASSIFICATION[[#This Row],[Classification (Generalized keyword)]]="",CLASSIFICATION[[#This Row],[Keyword]],CLASSIFICATION[[#This Row],[Classification (Generalized keyword)]]) -> +BPMN Process Model | I2: =_xlfn.CONCAT(CLASSIFICATION[[#This Row],[Project Stage Aggr]],",",CLASSIFICATION[[#This Row],[Functional Scope Aggr]],",",CLASSIFICATION[[#This Row],[Keyword]]) -> Design,Workflow model,+BPMN Process Model | J2: =_xlfn.CONCAT(CLASSIFICATION[[#This Row],[Project Stage Aggr]],",",CLASSIFICATION[[#This Row],[Functional Scope Aggr]],",",CLASSIFICATION[[#This Row],[Keyword Aggr]]) -> Design,Workflow model,+BPMN Process Model | K2: =_xlfn.CONCAT(CLASSIFICATION[[#This Row],[Project Stage Aggr]],",",CLASSIFICATION[[#This Row],[Functional Scope Aggr]],",",CLASSIFICATION[[#This Row],[Keyword Aggr]],",",CLASSIFICATION[[#This Row],[Importance]]) -> Design,Workflow model,+BPMN Process Model,5
C3: Custom Process Model | E3: -5 | F3: {=_xlfn.XLOOKUP(TRUE,A$2:A3<>"",A$2:A3,,,-1)} -> Design | G3: {=_xlfn.XLOOKUP(TRUE,B$2:B3<>"",B$2:B3,,,-1)} -> Workflow model | H3: =IF(CLASSIFICATION[[#This Row],[Classification (Generalized keyword)]]="",CLASSIFICATION[[#This Row],[Keyword]],CLASSIFICATION[[#This Row],[Classification (Generalized keyword)]]) -> Custom Process Model | I3: =_xlfn.CONCAT(CLASSIFICATION[[#This Row],[Project Stage Aggr]],",",CLASSIFICATION[[#This Row],[Functional Scope Aggr]],",",CLASSIFICATION[[#This Row],[Keyword]]) -> Design,Workflow model,Custom Process Model | J3: =_xlfn.CONCAT(CLASSIFICATION[[#This Row],[Project Stage Aggr]],",",CLASSIFICATION[[#This Row],[Functional Scope Aggr]],",",CLASSIFICATION[[#This Row],[Keyword Aggr]]) -> Design,Workflow model,Custom Process Model | K3: =_xlfn.CONCAT(CLASSIFICATION[[#This Row],[Project Stage Aggr]],",",CLASSIFICATION[[#This Row],[Functional Scope Aggr]],",",CLASSIFICATION[[#This Row],[Keyword Aggr]],",",CLASSIFICATION[[#This Row],[Importance]]) -> Design,Workflow model,Custom Process Model,-5
B4: Database model | C4: +Business Data Types | E4: 5 | F4: {=_xlfn.XLOOKUP(TRUE,A$2:A4<>"",A$2:A4,,,-1)} -> Design | G4: {=_xlfn.XLOOKUP(TRUE,B$2:B4<>"",B$2:B4,,,-1)} -> Database model | H4: =IF(CLASSIFICATION[[#This Row],[Classification (Generalized keyword)]]="",CLASSIFICATION[[#This Row],[Keyword]],CLASSIFICATION[[#This Row],[Classification (Generalized keyword)]]) -> +Business Data Types | I4: =_xlfn.CONCAT(CLASSIFICATION[[#This Row],[Project Stage Aggr]],",",CLASSIFICATION[[#This Row],[Functional Scope Aggr]],",",CLASSIFICATION[[#This Row],[Keyword]]) -> Design,Database model,+Business Data Types | J4: =_xlfn.CONCAT(CLASSIFICATION[[#This Row],[Project Stage Aggr]],",",CLASSIFICATION[[#This Row],[Functional Scope Aggr]],",",CLASSIFICATION[[#This Row],[Keyword Aggr]]) -> Design,Database model,+Business Data Types | K4: =_xlfn.CONCAT(CLASSIFICATION[[#This Row],[Project Stage Aggr]],",",CLASSIFICATION[[#This Row],[Functional Scope Aggr]],",",CLASSIFICATION[[#This Row],[Keyword Aggr]],",",CLASSIFICATION[[#This Row],[Importance]]) -> Design,Database model,+Business Data Types,5
C5: +Form-based Data | E5: 4 | F5: {=_xlfn.XLOOKUP(TRUE,A$2:A5<>"",A$2:A5,,,-1)} -> Design | G5: {=_xlfn.XLOOKUP(TRUE,B$2:B5<>"",B$2:B5,,,-1)} -> Database model | H5: =IF(CLASSIFICATION[[#This Row],[Classification (Generalized keyword)]]="",CLASSIFICATION[[#This Row],[Keyword]],CLASSIFICATION[[#This Row],[Classification (Generalized keyword)]]) -> +Form-based Data | I5: =_xlfn.CONCAT(CLASSIFICATION[[#This Row],[Project Stage Aggr]],",",CLASSIFICATION[[#This Row],[Functional Scope Aggr]],",",CLASSIFICATION[[#This Row],[Keyword]]) -> Design,Database model,+Form-based Data | J5: =_xlfn.CONCAT(CLASSIFICATION[[#This Row],[Project Stage Aggr]],",",CLASSIFICATION[[#This Row],[Functional Scope Aggr]],",",CLASSIFICATION[[#This Row],[Keyword Aggr]]) -> Design,Database model,+Form-based Data | K5: =_xlfn.CONCAT(CLASSIFICATION[[#This Row],[Project Stage Aggr]],",",CLASSIFICATION[[#This Row],[Functional Scope Aggr]],",",CLASSIFICATION[[#This Row],[Keyword Aggr]],",",CLASSIFICATION[[#This Row],[Importance]]) -> Design,Database model,+Form-based Data,4
C6: +Item-Detail | E6: 3 | F6: {=_xlfn.XLOOKUP(TRUE,A$2:A6<>"",A$2:A6,,,-1)} -> Design | G6: {=_xlfn.XLOOKUP(TRUE,B$2:B6<>"",B$2:B6,,,-1)} -> Database model | H6: =IF(CLASSIFICATION[[#This Row],[Classification (Generalized keyword)]]="",CLASSIFICATION[[#This Row],[Keyword]],CLASSIFICATION[[#This Row],[Classification (Generalized keyword)]]) -> +Item-Detail | I6: =_xlfn.CONCAT(CLASSIFICATION[[#This Row],[Project Stage Aggr]],",",CLASSIFICATION[[#This Row],[Functional Scope Aggr]],",",CLASSIFICATION[[#This Row],[Keyword]]) -> Design,Database model,+Item-Detail | J6: =_xlfn.CONCAT(CLASSIFICATION[[#This Row],[Project Stage Aggr]],",",CLASSIFICATION[[#This Row],[Functional Scope Aggr]],",",CLASSIFICATION[[#This Row],[Keyword Aggr]]) -> Design,Database model,+Item-Detail | K6: =_xlfn.CONCAT(CLASSIFICATION[[#This Row],[Project Stage Aggr]],",",CLASSIFICATION[[#This Row],[Functional Scope Aggr]],",",CLASSIFICATION[[#This Row],[Keyword Aggr]],",",CLASSIFICATION[[#This Row],[Importance]]) -> Design,Database model,+Item-Detail,3
C7: +Lookup/Drop-down | E7: 3 | F7: {=_xlfn.XLOOKUP(TRUE,A$2:A7<>"",A$2:A7,,,-1)} -> Design | G7: {=_xlfn.XLOOKUP(TRUE,B$2:B7<>"",B$2:B7,,,-1)} -> Database model | H7: =IF(CLASSIFICATION[[#This Row],[Classification (Generalized keyword)]]="",CLASSIFICATION[[#This Row],[Keyword]],CLASSIFICATION[[#This Row],[Classification (Generalized keyword)]]) -> +Lookup/Drop-down | I7: =_xlfn.CONCAT(CLASSIFICATION[[#This Row],[Project Stage Aggr]],",",CLASSIFICATION[[#This Row],[Functional Scope Aggr]],",",CLASSIFICATION[[#This Row],[Keyword]]) -> Design,Database model,+Lookup/Drop-down | J7: =_xlfn.CONCAT(CLASSIFICATION[[#This Row],[Project Stage Aggr]],",",CLASSIFICATION[[#This Row],[Functional Scope Aggr]],",",CLASSIFICATION[[#This Row],[Keyword Aggr]]) -> Design,Database model,+Lookup/Drop-down | K7: =_xlfn.CONCAT(CLASSIFICATION[[#This Row],[Project Stage Aggr]],",",CLASSIFICATION[[#This Row],[Functional Scope Aggr]],",",CLASSIFICATION[[#This Row],[Keyword Aggr]],",",CLASSIFICATION[[#This Row],[Importance]]) -> Design,Database model,+Lookup/Drop-down,3
C8: +Predefined Entities | E8: 4 | F8: {=_xlfn.XLOOKUP(TRUE,A$2:A8<>"",A$2:A8,,,-1)} -> Design | G8: {=_xlfn.XLOOKUP(TRUE,B$2:B8<>"",B$2:B8,,,-1)} -> Database model | H8: =IF(CLASSIFICATION[[#This Row],[Classification (Generalized keyword)]]="",CLASSIFICATION[[#This Row],[Keyword]],CLASSIFICATION[[#This Row],[Classification (Generalized keyword)]]) -> +Predefined Entities | I8: =_xlfn.CONCAT(CLASSIFICATION[[#This Row],[Project Stage Aggr]],",",CLASSIFICATION[[#This Row],[Functional Scope Aggr]],",",CLASSIFICATION[[#This Row],[Keyword]]) -> Design,Database model,+Predefined Entities | J8: =_xlfn.CONCAT(CLASSIFICATION[[#This Row],[Project Stage Aggr]],",",CLASSIFICATION[[#This Row],[Functional Scope Aggr]],",",CLASSIFICATION[[#This Row],[Keyword Aggr]]) -> Design,Database model,+Predefined Entities | K8: =_xlfn.CONCAT(CLASSIFICATION[[#This Row],[Project Stage Aggr]],",",CLASSIFICATION[[#This Row],[Functional Scope Aggr]],",",CLASSIFICATION[[#This Row],[Keyword Aggr]],",",CLASSIFICATION[[#This Row],[Importance]]) -> Design,Database model,+Predefined Entities,4
C9: Association | D9: Domain Model | E9: -3 | F9: {=_xlfn.XLOOKUP(TRUE,A$2:A9<>"",A$2:A9,,,-1)} -> Design | G9: {=_xlfn.XLOOKUP(TRUE,B$2:B9<>"",B$2:B9,,,-1)} -> Database model | H9: =IF(CLASSIFICATION[[#This Row],[Classification (Generalized keyword)]]="",CLASSIFICATION[[#This Row],[Keyword]],CLASSIFICATION[[#This Row],[Classification (Generalized keyword)]]) -> Domain Model | I9: =_xlfn.CONCAT(CLASSIFICATION[[#This Row],[Project Stage Aggr]],",",CLASSIFICATION[[#This Row],[Functional Scope Aggr]],",",CLASSIFICATION[[#This Row],[Keyword]]) -> Design,Database model,Association | J9: =_xlfn.CONCAT(CLASSIFICATION[[#This Row],[Project Stage Aggr]],",",CLASSIFICATION[[#This Row],[Functional Scope Aggr]],",",CLASSIFICATION[[#This Row],[Keyword Aggr]]) -> Design,Database model,Domain Model | K9: =_xlfn.CONCAT(CLASSIFICATION[[#This Row],[Project Stage Aggr]],",",CLASSIFICATION[[#This Row],[Functional Scope Aggr]],",",CLASSIFICATION[[#This Row],[Keyword Aggr]],",",CLASSIFICATION[[#This Row],[Importance]]) -> Design,Database model,Domain Model,-3
C10: Conditional Expressions | E10: -2 | F10: {=_xlfn.XLOOKUP(TRUE,A$2:A10<>"",A$2:A10,,,-1)} -> Design | G10: {=_xlfn.XLOOKUP(TRUE,B$2:B10<>"",B$2:B10,,,-1)} -> Database model | H10: =IF(CLASSIFICATION[[#This Row],[Classification (Generalized keyword)]]="",CLASSIFICATION[[#This Row],[Keyword]],CLASSIFICATION[[#This Row],[Classification (Generalized keyword)]]) -> Conditional Expressions | I10: =_xlfn.CONCAT(CLASSIFICATION[[#This Row],[Project Stage Aggr]],",",CLASSIFICATION[[#This Row],[Functional Scope Aggr]],",",CLASSIFICATION[[#This Row],[Keyword]]) -> Design,Database model,Conditional Expressions | J10: =_xlfn.CONCAT(CLASSIFICATION[[#This Row],[Project Stage Aggr]],",",CLASSIFICATION[[#This Row],[Functional Scope Aggr]],",",CLASSIFICATION[[#This Row],[Keyword Aggr]]) -> Design,Database model,Conditional Expressions | K10: =_xlfn.CONCAT(CLASSIFICATION[[#This Row],[Project Stage Aggr]],",",CLASSIFICATION[[#This Row],[Functional Scope Aggr]],",",CLASSIFICATION[[#This Row],[Keyword Aggr]],",",CLASSIFICATION[[#This Row],[Importance]]) -> Design,Database model,Conditional Expressions,-2
C11: Constraints | E11: -2 | F11: {=_xlfn.XLOOKUP(TRUE,A$2:A11<>"",A$2:A11,,,-1)} -> Design | G11: {=_xlfn.XLOOKUP(TRUE,B$2:B11<>"",B$2:B11,,,-1)} -> Database model | H11: =IF(CLASSIFICATION[[#This Row],[Classification (Generalized keyword)]]="",CLASSIFICATION[[#This Row],[Keyword]],CLASSIFICATION[[#This Row],[Classification (Generalized keyword)]]) -> Constraints | I11: =_xlfn.CONCAT(CLASSIFICATION[[#This Row],[Project Stage Aggr]],",",CLASSIFICATION[[#This Row],[Functional Scope Aggr]],",",CLASSIFICATION[[#This Row],[Keyword]]) -> Design,Database model,Constraints | J11: =_xlfn.CONCAT(CLASSIFICATION[[#This Row],[Project Stage Aggr]],",",CLASSIFICATION[[#This Row],[Functional Scope Aggr]],",",CLASSIFICATION[[#This Row],[Keyword Aggr]]) -> Design,Database model,Constraints | K11: =_xlfn.CONCAT(CLASSIFICATION[[#This Row],[Project Stage Aggr]],",",CLASSIFICATION[[#This Row],[Functional Scope Aggr]],",",CLASSIFICATION[[#This Row],[Keyword Aggr]],",",CLASSIFICATION[[#This Row],[Importance]]) -> Design,Database model,Constraints,-2
C12: Data Structure | E12: -3 | F12: {=_xlfn.XLOOKUP(TRUE,A$2:A12<>"",A$2:A12,,,-1)} -> Design | G12: {=_xlfn.XLOOKUP(TRUE,B$2:B12<>"",B$2:B12,,,-1)} -> Database model | H12: =IF(CLASSIFICATION[[#This Row],[Classification (Generalized keyword)]]="",CLASSIFICATION[[#This Row],[Keyword]],CLASSIFICATION[[#This Row],[Classification (Generalized keyword)]]) -> Data Structure | I12: =_xlfn.CONCAT(CLASSIFICATION[[#This Row],[Project Stage Aggr]],",",CLASSIFICATION[[#This Row],[Functional Scope Aggr]],",",CLASSIFICATION[[#This Row],[Keyword]]) -> Design,Database model,Data Structure | J12: =_xlfn.CONCAT(CLASSIFICATION[[#This Row],[Project Stage Aggr]],",",CLASSIFICATION[[#This Row],[Functional Scope Aggr]],",",CLASSIFICATION[[#This Row],[Keyword Aggr]]) -> Design,Database model,Data Structure | K12: =_xlfn.CONCAT(CLASSIFICATION[[#This Row],[Project Stage Aggr]],",",CLASSIFICATION[[#This Row],[Functional Scope Aggr]],",",CLASSIFICATION[[#This Row],[Keyword Aggr]],",",CLASSIFICATION[[#This Row],[Importance]]) -> Design,Database model,Data Structure,-3
C13: Data Types | D13: IT Data Types | E13: -4 | F13: {=_xlfn.XLOOKUP(TRUE,A$2:A13<>"",A$2:A13,,,-1)} -> Design | G13: {=_xlfn.XLOOKUP(TRUE,B$2:B13<>"",B$2:B13,,,-1)} -> Database model | H13: =IF(CLASSIFICATION[[#This Row],[Classification (Generalized keyword)]]="",CLASSIFICATION[[#This Row],[Keyword]],CLASSIFICATION[[#This Row],[Classification (Generalized keyword)]]) -> IT Data Types | I13: =_xlfn.CONCAT(CLASSIFICATION[[#This Row],[Project Stage Aggr]],",",CLASSIFICATION[[#This Row],[Functional Scope Aggr]],",",CLASSIFICATION[[#This Row],[Keyword]]) -> Design,Database model,Data Types | J13: =_xlfn.CONCAT(CLASSIFICATION[[#This Row],[Project Stage Aggr]],",",CLASSIFICATION[[#This Row],[Functional Scope Aggr]],",",CLASSIFICATION[[#This Row],[Keyword Aggr]]) -> Design,Database model,IT Data Types | K13: =_xlfn.CONCAT(CLASSIFICATION[[#This Row],[Project Stage Aggr]],",",CLASSIFICATION[[#This Row],[Functional Scope Aggr]],",",CLASSIFICATION[[#This Row],[Keyword Aggr]],",",CLASSIFICATION[[#This Row],[Importance]]) -> Design,Database model,IT Data Types,-4
C14: Denormalization | E14: -3 | F14: {=_xlfn.XLOOKUP(TRUE,A$2:A14<>"",A$2:A14,,,-1)} -> Design | G14: {=_xlfn.XLOOKUP(TRUE,B$2:B14<>"",B$2:B14,,,-1)} -> Database model | H14: =IF(CLASSIFICATION[[#This Row],[Classification (Generalized keyword)]]="",CLASSIFICATION[[#This Row],[Keyword]],CLASSIFICATION[[#This Row],[Classification (Generalized keyword)]]) -> Denormalization | I14: =_xlfn.CONCAT(CLASSIFICATION[[#This Row],[Project Stage Aggr]],",",CLASSIFICATION[[#This Row],[Functional Scope Aggr]],",",CLASSIFICATION[[#This Row],[Keyword]]) -> Design,Database model,Denormalization | J14: =_xlfn.CONCAT(CLASSIFICATION[[#This Row],[Project Stage Aggr]],",",CLASSIFICATION[[#This Row],[Functional Scope Aggr]],",",CLASSIFICATION[[#This Row],[Keyword Aggr]]) -> Design,Database model,Denormalization | K14: =_xlfn.CONCAT(CLASSIFICATION[[#This Row],[Project Stage Aggr]],",",CLASSIFICATION[[#This Row],[Functional Scope Aggr]],",",CLASSIFICATION[[#This Row],[Keyword Aggr]],",",CLASSIFICATION[[#This Row],[Importance]]) -> Design,Database model,Denormalization,-3
C15: Domain Model | E15: -3 | F15: {=_xlfn.XLOOKUP(TRUE,A$2:A15<>"",A$2:A15,,,-1)} -> Design | G15: {=_xlfn.XLOOKUP(TRUE,B$2:B15<>"",B$2:B15,,,-1)} -> Database model | H15: =IF(CLASSIFICATION[[#This Row],[Classification (Generalized keyword)]]="",CLASSIFICATION[[#This Row],[Keyword]],CLASSIFICATION[[#This Row],[Classification (Generalized keyword)]]) -> Domain Model | I15: =_xlfn.CONCAT(CLASSIFICATION[[#This Row],[Project Stage Aggr]],",",CLASSIFICATION[[#This Row],[Functional Scope Aggr]],",",CLASSIFICATION[[#This Row],[Keyword]]) -> Design,Database model,Domain Model | J15: =_xlfn.CONCAT(CLASSIFICATION[[#This Row],[Project Stage Aggr]],",",CLASSIFICATION[[#This Row],[Functional Scope Aggr]],",",CLASSIFICATION[[#This Row],[Keyword Aggr]]) -> Design,Database model,Domain Model | K15: =_xlfn.CONCAT(CLASSIFICATION[[#This Row],[Project Stage Aggr]],",",CLASSIFICATION[[#This Row],[Functional Scope Aggr]],",",CLASSIFICATION[[#This Row],[Keyword Aggr]],",",CLASSIFICATION[[#This Row],[Importance]]) -> Design,Database model,Domain Model,-3
C16: Entity Diagrams | E16: -4 | F16: {=_xlfn.XLOOKUP(TRUE,A$2:A16<>"",A$2:A16,,,-1)} -> Design | G16: {=_xlfn.XLOOKUP(TRUE,B$2:B16<>"",B$2:B16,,,-1)} -> Database model | H16: =IF(CLASSIFICATION[[#This Row],[Classification (Generalized keyword)]]="",CLASSIFICATION[[#This Row],[Keyword]],CLASSIFICATION[[#This Row],[Classification (Generalized keyword)]]) -> Entity Diagrams | I16: =_xlfn.CONCAT(CLASSIFICATION[[#This Row],[Project Stage Aggr]],",",CLASSIFICATION[[#This Row],[Functional Scope Aggr]],",",CLASSIFICATION[[#This Row],[Keyword]]) -> Design,Database model,Entity Diagrams | J16: =_xlfn.CONCAT(CLASSIFICATION[[#This Row],[Project Stage Aggr]],",",CLASSIFICATION[[#This Row],[Functional Scope Aggr]],",",CLASSIFICATION[[#This Row],[Keyword Aggr]]) -> Design,Database model,Entity Diagrams | K16: =_xlfn.CONCAT(CLASSIFICATION[[#This Row],[Project Stage Aggr]],",",CLASSIFICATION[[#This Row],[Functional Scope Aggr]],",",CLASSIFICATION[[#This Row],[Keyword Aggr]],",",CLASSIFICATION[[#This Row],[Importance]]) -> Design,Database model,Entity Diagrams,-4
C17: Entity relationships | D17: Entity Diagrams | E17: -4 | F17: {=_xlfn.XLOOKUP(TRUE,A$2:A17<>"",A$2:A17,,,-1)} -> Design | G17: {=_xlfn.XLOOKUP(TRUE,B$2:B17<>"",B$2:B17,,,-1)} -> Database model | H17: =IF(CLASSIFICATION[[#This Row],[Classification (Generalized keyword)]]="",CLASSIFICATION[[#This Row],[Keyword]],CLASSIFICATION[[#This Row],[Classification (Generalized keyword)]]) -> Entity Diagrams | I17: =_xlfn.CONCAT(CLASSIFICATION[[#This Row],[Project Stage Aggr]],",",CLASSIFICATION[[#This Row],[Functional Scope Aggr]],",",CLASSIFICATION[[#This Row],[Keyword]]) -> Design,Database model,Entity relationships | J17: =_xlfn.CONCAT(CLASSIFICATION[[#This Row],[Project Stage Aggr]],",",CLASSIFICATION[[#This Row],[Functional Scope Aggr]],",",CLASSIFICATION[[#This Row],[Keyword Aggr]]) -> Design,Database model,Entity Diagrams | K17: =_xlfn.CONCAT(CLASSIFICATION[[#This Row],[Project Stage Aggr]],",",CLASSIFICATION[[#This Row],[Functional Scope Aggr]],",",CLASSIFICATION[[#This Row],[Keyword Aggr]],",",CLASSIFICATION[[#This Row],[Importance]]) -> Design,Database model,Entity Diagrams,-4
C18: Enumeration | E18: -1 | F18: {=_xlfn.XLOOKUP(TRUE,A$2:A18<>"",A$2:A18,,,-1)} -> Design | G18: {=_xlfn.XLOOKUP(TRUE,B$2:B18<>"",B$2:B18,,,-1)} -> Database model | H18: =IF(CLASSIFICATION[[#This Row],[Classification (Generalized keyword)]]="",CLASSIFICATION[[#This Row],[Keyword]],CLASSIFICATION[[#This Row],[Classification (Generalized keyword)]]) -> Enumeration | I18: =_xlfn.CONCAT(CLASSIFICATION[[#This Row],[Project Stage Aggr]],",",CLASSIFICATION[[#This Row],[Functional Scope Aggr]],",",CLASSIFICATION[[#This Row],[Keyword]]) -> Design,Database model,Enumeration | J18: =_xlfn.CONCAT(CLASSIFICATION[[#This Row],[Project Stage Aggr]],",",CLASSIFICATION[[#This Row],[Functional Scope Aggr]],",",CLASSIFICATION[[#This Row],[Keyword Aggr]]) -> Design,Database model,Enumeration | K18: =_xlfn.CONCAT(CLASSIFICATION[[#This Row],[Project Stage Aggr]],",",CLASSIFICATION[[#This Row],[Functional Scope Aggr]],",",CLASSIFICATION[[#This Row],[Keyword Aggr]],",",CLASSIFICATION[[#This Row],[Importance]]) -> Design,Database model,Enumeration,-1
C19: Expressions | E19: -1 | F19: {=_xlfn.XLOOKUP(TRUE,A$2:A19<>"",A$2:A19,,,-1)} -> Design | G19: {=_xlfn.XLOOKUP(TRUE,B$2:B19<>"",B$2:B19,,,-1)} -> Database model | H19: =IF(CLASSIFICATION[[#This Row],[Classification (Generalized keyword)]]="",CLASSIFICATION[[#This Row],[Keyword]],CLASSIFICATION[[#This Row],[Classification (Generalized keyword)]]) -> Expressions | I19: =_xlfn.CONCAT(CLASSIFICATION[[#This Row],[Project Stage Aggr]],",",CLASSIFICATION[[#This Row],[Functional Scope Aggr]],",",CLASSIFICATION[[#This Row],[Keyword]]) -> Design,Database model,Expressions | J19: =_xlfn.CONCAT(CLASSIFICATION[[#This Row],[Project Stage Aggr]],",",CLASSIFICATION[[#This Row],[Functional Scope Aggr]],",",CLASSIFICATION[[#This Row],[Keyword Aggr]]) -> Design,Database model,Expressions | K19: =_xlfn.CONCAT(CLASSIFICATION[[#This Row],[Project Stage Aggr]],",",CLASSIFICATION[[#This Row],[Functional Scope Aggr]],",",CLASSIFICATION[[#This Row],[Keyword Aggr]],",",CLASSIFICATION[[#This Row],[Importance]]) -> Design,Database model,Expressions,-1
C20: Foreign Key | D20: Relational Database | E20: -5 | F20: {=_xlfn.XLOOKUP(TRUE,A$2:A20<>"",A$2:A20,,,-1)} -> Design | G20: {=_xlfn.XLOOKUP(TRUE,B$2:B20<>"",B$2:B20,,,-1)} -> Database model | H20: =IF(CLASSIFICATION[[#This Row],[Classification (Generalized keyword)]]="",CLASSIFICATION[[#This Row],[Keyword]],CLASSIFICATION[[#This Row],[Classification (Generalized keyword)]]) -> Relational Database | I20: =_xlfn.CONCAT(CLASSIFICATION[[#This Row],[Project Stage Aggr]],",",CLASSIFICATION[[#This Row],[Functional Scope Aggr]],",",CLASSIFICATION[[#This Row],[Keyword]]) -> Design,Database model,Foreign Key | J20: =_xlfn.CONCAT(CLASSIFICATION[[#This Row],[Project Stage Aggr]],",",CLASSIFICATION[[#This Row],[Functional Scope Aggr]],",",CLASSIFICATION[[#This Row],[Keyword Aggr]]) -> Design,Database model,Relational Database | K20: =_xlfn.CONCAT(CLASSIFICATION[[#This Row],[Project Stage Aggr]],",",CLASSIFICATION[[#This Row],[Functional Scope Aggr]],",",CLASSIFICATION[[#This Row],[Keyword Aggr]],",",CLASSIFICATION[[#This Row],[Importance]]) -> Design,Database model,Relational Database,-5
C21: Indexes | D21: Relational Database | E21: -5 | F21: {=_xlfn.XLOOKUP(TRUE,A$2:A21<>"",A$2:A21,,,-1)} -> Design | G21: {=_xlfn.XLOOKUP(TRUE,B$2:B21<>"",B$2:B21,,,-1)} -> Database model | H21: =IF(CLASSIFICATION[[#This Row],[Classification (Generalized keyword)]]="",CLASSIFICATION[[#This Row],[Keyword]],CLASSIFICATION[[#This Row],[Classification (Generalized keyword)]]) -> Relational Database | I21: =_xlfn.CONCAT(CLASSIFICATION[[#This Row],[Project Stage Aggr]],",",CLASSIFICATION[[#This Row],[Functional Scope Aggr]],",",CLASSIFICATION[[#This Row],[Keyword]]) -> Design,Database model,Indexes | J21: =_xlfn.CONCAT(CLASSIFICATION[[#This Row],[Project Stage Aggr]],",",CLASSIFICATION[[#This Row],[Functional Scope Aggr]],",",CLASSIFICATION[[#This Row],[Keyword Aggr]]) -> Design,Database model,Relational Database | K21: =_xlfn.CONCAT(CLASSIFICATION[[#This Row],[Project Stage Aggr]],",",CLASSIFICATION[[#This Row],[Functional Scope Aggr]],",",CLASSIFICATION[[#This Row],[Keyword Aggr]],",",CLASSIFICATION[[#This Row],[Importance]]) -> Design,Database model,Relational Database,-5
C22: Many-to-Many | D22: Relational Database | E22: -5 | F22: {=_xlfn.XLOOKUP(TRUE,A$2:A22<>"",A$2:A22,,,-1)} -> Design | G22: {=_xlfn.XLOOKUP(TRUE,B$2:B22<>"",B$2:B22,,,-1)} -> Database model | H22: =IF(CLASSIFICATION[[#This Row],[Classification (Generalized keyword)]]="",CLASSIFICATION[[#This Row],[Keyword]],CLASSIFICATION[[#This Row],[Classification (Generalized keyword)]]) -> Relational Database | I22: =_xlfn.CONCAT(CLASSIFICATION[[#This Row],[Project Stage Aggr]],",",CLASSIFICATION[[#This Row],[Functional Scope Aggr]],",",CLASSIFICATION[[#This Row],[Keyword]]) -> Design,Database model,Many-to-Many | J22: =_xlfn.CONCAT(CLASSIFICATION[[#This Row],[Project Stage Aggr]],",",CLASSIFICATION[[#This Row],[Functional Scope Aggr]],",",CLASSIFICATION[[#This Row],[Keyword Aggr]]) -> Design,Database model,Relational Database | K22: =_xlfn.CONCAT(CLASSIFICATION[[#This Row],[Project Stage Aggr]],",",CLASSIFICATION[[#This Row],[Functional Scope Aggr]],",",CLASSIFICATION[[#This Row],[Keyword Aggr]],",",CLASSIFICATION[[#This Row],[Importance]]) -> Design,Database model,Relational Database,-5
C23: One-to-Many | D23: Relational Database | E23: -5 | F23: {=_xlfn.XLOOKUP(TRUE,A$2:A23<>"",A$2:A23,,,-1)} -> Design | G23: {=_xlfn.XLOOKUP(TRUE,B$2:B23<>"",B$2:B23,,,-1)} -> Database model | H23: =IF(CLASSIFICATION[[#This Row],[Classification (Generalized keyword)]]="",CLASSIFICATION[[#This Row],[Keyword]],CLASSIFICATION[[#This Row],[Classification (Generalized keyword)]]) -> Relational Database | I23: =_xlfn.CONCAT(CLASSIFICATION[[#This Row],[Project Stage Aggr]],",",CLASSIFICATION[[#This Row],[Functional Scope Aggr]],",",CLASSIFICATION[[#This Row],[Keyword]]) -> Design,Database model,One-to-Many | J23: =_xlfn.CONCAT(CLASSIFICATION[[#This Row],[Project Stage Aggr]],",",CLASSIFICATION[[#This Row],[Functional Scope Aggr]],",",CLASSIFICATION[[#This Row],[Keyword Aggr]]) -> Design,Database model,Relational Database | K23: =_xlfn.CONCAT(CLASSIFICATION[[#This Row],[Project Stage Aggr]],",",CLASSIFICATION[[#This Row],[Functional Scope Aggr]],",",CLASSIFICATION[[#This Row],[Keyword Aggr]],",",CLASSIFICATION[[#This Row],[Importance]]) -> Design,Database model,Relational Database,-5
C24: One-to-One | D24: Relational Database | E24: -5 | F24: {=_xlfn.XLOOKUP(TRUE,A$2:A24<>"",A$2:A24,,,-1)} -> Design | G24: {=_xlfn.XLOOKUP(TRUE,B$2:B24<>"",B$2:B24,,,-1)} -> Database model | H24: =IF(CLASSIFICATION[[#This Row],[Classification (Generalized keyword)]]="",CLASSIFICATION[[#This Row],[Keyword]],CLASSIFICATION[[#This Row],[Classification (Generalized keyword)]]) -> Relational Database | I24: =_xlfn.CONCAT(CLASSIFICATION[[#This Row],[Project Stage Aggr]],",",CLASSIFICATION[[#This Row],[Functional Scope Aggr]],",",CLASSIFICATION[[#This Row],[Keyword]]) -> Design,Database model,One-to-One | J24: =_xlfn.CONCAT(CLASSIFICATION[[#This Row],[Project Stage Aggr]],",",CLASSIFICATION[[#This Row],[Functional Scope Aggr]],",",CLASSIFICATION[[#This Row],[Keyword Aggr]]) -> Design,Database model,Relational Database | K24: =_xlfn.CONCAT(CLASSIFICATION[[#This Row],[Project Stage Aggr]],",",CLASSIFICATION[[#This Row],[Functional Scope Aggr]],",",CLASSIFICATION[[#This Row],[Keyword Aggr]],",",CLASSIFICATION[[#This Row],[Importance]]) -> Design,Database model,Relational Database,-5
C25: Primary Key | D25: Relational Database | E25: -5 | F25: {=_xlfn.XLOOKUP(TRUE,A$2:A25<>"",A$2:A25,,,-1)} -> Design | G25: {=_xlfn.XLOOKUP(TRUE,B$2:B25<>"",B$2:B25,,,-1)} -> Database model | H25: =IF(CLASSIFICATION[[#This Row],[Classification (Generalized keyword)]]="",CLASSIFICATION[[#This Row],[Keyword]],CLASSIFICATION[[#This Row],[Classification (Generalized keyword)]]) -> Relational Database | I25: =_xlfn.CONCAT(CLASSIFICATION[[#This Row],[Project Stage Aggr]],",",CLASSIFICATION[[#This Row],[Functional Scope Aggr]],",",CLASSIFICATION[[#This Row],[Keyword]]) -> Design,Database model,Primary Key | J25: =_xlfn.CONCAT(CLASSIFICATION[[#This Row],[Project Stage Aggr]],",",CLASSIFICATION[[#This Row],[Functional Scope Aggr]],",",CLASSIFICATION[[#This Row],[Keyword Aggr]]) -> Design,Database model,Relational Database | K25: =_xlfn.CONCAT(CLASSIFICATION[[#This Row],[Project Stage Aggr]],",",CLASSIFICATION[[#This Row],[Functional Scope Aggr]],",",CLASSIFICATION[[#This Row],[Keyword Aggr]],",",CLASSIFICATION[[#This Row],[Importance]]) -> Design,Database model,Relational Database,-5
C26: XML | D26: XML/XPath | E26: -4 | F26: {=_xlfn.XLOOKUP(TRUE,A$2:A26<>"",A$2:A26,,,-1)} -> Design | G26: {=_xlfn.XLOOKUP(TRUE,B$2:B26<>"",B$2:B26,,,-1)} -> Database model | H26: =IF(CLASSIFICATION[[#This Row],[Classification (Generalized keyword)]]="",CLASSIFICATION[[#This Row],[Keyword]],CLASSIFICATION[[#This Row],[Classification (Generalized keyword)]]) -> XML/XPath | I26: =_xlfn.CONCAT(CLASSIFICATION[[#This Row],[Project Stage Aggr]],",",CLASSIFICATION[[#This Row],[Functional Scope Aggr]],",",CLASSIFICATION[[#This Row],[Keyword]]) -> Design,Database model,XML | J26: =_xlfn.CONCAT(CLASSIFICATION[[#This Row],[Project Stage Aggr]],",",CLASSIFICATION[[#This Row],[Functional Scope Aggr]],",",CLASSIFICATION[[#This Row],[Keyword Aggr]]) -> Design,Database model,XML/XPath | K26: =_xlfn.CONCAT(CLASSIFICATION[[#This Row],[Project Stage Aggr]],",",CLASSIFICATION[[#This Row],[Functional Scope Aggr]],",",CLASSIFICATION[[#This Row],[Keyword Aggr]],",",CLASSIFICATION[[#This Row],[Importance]]) -> Design,Database model,XML/XPath,-4
C27: XPath | D27: XML/XPath | E27: -4 | F27: {=_xlfn.XLOOKUP(TRUE,A$2:A27<>"",A$2:A27,,,-1)} -> Design | G27: {=_xlfn.XLOOKUP(TRUE,B$2:B27<>"",B$2:B27,,,-1)} -> Database model | H27: =IF(CLASSIFICATION[[#This Row],[Classification (Generalized keyword)]]="",CLASSIFICATION[[#This Row],[Keyword]],CLASSIFICATION[[#This Row],[Classification (Generalized keyword)]]) -> XML/XPath | I27: =_xlfn.CONCAT(CLASSIFICATION[[#This Row],[Project Stage Aggr]],",",CLASSIFICATION[[#This Row],[Functional Scope Aggr]],",",CLASSIFICATION[[#This Row],[Keyword]]) -> Design,Database model,XPath | J27: =_xlfn.CONCAT(CLASSIFICATION[[#This Row],[Project Stage Aggr]],",",CLASSIFICATION[[#This Row],[Functional Scope Aggr]],",",CLASSIFICATION[[#This Row],[Keyword Aggr]]) -> Design,Database model,XML/XPath | K27: =_xlfn.CONCAT(CLASSIFICATION[[#This Row],[Project Stage Aggr]],",",CLASSIFICATION[[#This Row],[Functional Scope Aggr]],",",CLASSIFICATION[[#This Row],[Keyword Aggr]],",",CLASSIFICATION[[#This Row],[Importance]]) -> Design,Database model,XML/XPath,-4
C28: XML/Xpath | E28: -4 | F28: {=_xlfn.XLOOKUP(TRUE,A$2:A28<>"",A$2:A28,,,-1)} -> Design | G28: {=_xlfn.XLOOKUP(TRUE,B$2:B28<>"",B$2:B28,,,-1)} -> Database model | H28: =IF(CLASSIFICATION[[#This Row],[Classification (Generalized keyword)]]="",CLASSIFICATION[[#This Row],[Keyword]],CLASSIFICATION[[#This Row],[Classification (Generalized keyword)]]) -> XML/Xpath | I28: =_xlfn.CONCAT(CLASSIFICATION[[#This Row],[Project Stage Aggr]],",",CLASSIFICATION[[#This Row],[Functional Scope Aggr]],",",CLASSIFICATION[[#This Row],[Keyword]]) -> Design,Database model,XML/Xpath | J28: =_xlfn.CONCAT(CLASSIFICATION[[#This Row],[Project Stage Aggr]],",",CLASSIFICATION[[#This Row],[Functional Scope Aggr]],",",CLASSIFICATION[[#This Row],[Keyword Aggr]]) -> Design,Database model,XML/Xpath | K28: =_xlfn.CONCAT(CLASSIFICATION[[#This Row],[Project Stage Aggr]],",",CLASSIFICATION[[#This Row],[Functional Scope Aggr]],",",CLASSIFICATION[[#This Row],[Keyword Aggr]],",",CLASSIFICATION[[#This Row],[Importance]]) -> Design,Database model,XML/Xpath,-4
B29: UI model | C29: +App templates | D29: +App templates | E29: 4 | F29: {=_xlfn.XLOOKUP(TRUE,A$2:A29<>"",A$2:A29,,,-1)} -> Design | G29: {=_xlfn.XLOOKUP(TRUE,B$2:B29<>"",B$2:B29,,,-1)} -> UI model | H29: =IF(CLASSIFICATION[[#This Row],[Classification (Generalized keyword)]]="",CLASSIFICATION[[#This Row],[Keyword]],CLASSIFICATION[[#This Row],[Classification (Generalized keyword)]]) -> +App templates | I29: =_xlfn.CONCAT(CLASSIFICATION[[#This Row],[Project Stage Aggr]],",",CLASSIFICATION[[#This Row],[Functional Scope Aggr]],",",CLASSIFICATION[[#This Row],[Keyword]]) -> Design,UI model,+App templates | J29: =_xlfn.CONCAT(CLASSIFICATION[[#This Row],[Project Stage Aggr]],",",CLASSIFICATION[[#This Row],[Functional Scope Aggr]],",",CLASSIFICATION[[#This Row],[Keyword Aggr]]) -> Design,UI model,+App templates | K29: =_xlfn.CONCAT(CLASSIFICATION[[#This Row],[Project Stage Aggr]],",",CLASSIFICATION[[#This Row],[Functional Scope Aggr]],",",CLASSIFICATION[[#This Row],[Keyword Aggr]],",",CLASSIFICATION[[#This Row],[Importance]]) -> Design,UI model,+App templates,4
C30: +App templates (CUBBE) | D30: +App templates | E30: 4 | F30: {=_xlfn.XLOOKUP(TRUE,A$2:A30<>"",A$2:A30,,,-1)} -> Design | G30: {=_xlfn.XLOOKUP(TRUE,B$2:B30<>"",B$2:B30,,,-1)} -> UI model | H30: =IF(CLASSIFICATION[[#This Row],[Classification (Generalized keyword)]]="",CLASSIFICATION[[#This Row],[Keyword]],CLASSIFICATION[[#This Row],[Classification (Generalized keyword)]]) -> +App templates | I30: =_xlfn.CONCAT(CLASSIFICATION[[#This Row],[Project Stage Aggr]],",",CLASSIFICATION[[#This Row],[Functional Scope Aggr]],",",CLASSIFICATION[[#This Row],[Keyword]]) -> Design,UI model,+App templates (CUBBE) | J30: =_xlfn.CONCAT(CLASSIFICATION[[#This Row],[Project Stage Aggr]],",",CLASSIFICATION[[#This Row],[Functional Scope Aggr]],",",CLASSIFICATION[[#This Row],[Keyword Aggr]]) -> Design,UI model,+App templates | K30: =_xlfn.CONCAT(CLASSIFICATION[[#This Row],[Project Stage Aggr]],",",CLASSIFICATION[[#This Row],[Functional Scope Aggr]],",",CLASSIFICATION[[#This Row],[Keyword Aggr]],",",CLASSIFICATION[[#This Row],[Importance]]) -> Design,UI model,+App templates,4
C31: +Business Data Types | E31: 5 | F31: {=_xlfn.XLOOKUP(TRUE,A$2:A31<>"",A$2:A31,,,-1)} -> Design | G31: {=_xlfn.XLOOKUP(TRUE,B$2:B31<>"",B$2:B31,,,-1)} -> UI model | H31: =IF(CLASSIFICATION[[#This Row],[Classification (Generalized keyword)]]="",CLASSIFICATION[[#This Row],[Keyword]],CLASSIFICATION[[#This Row],[Classification (Generalized keyword)]]) -> +Business Data Types | I31: =_xlfn.CONCAT(CLASSIFICATION[[#This Row],[Project Stage Aggr]],",",CLASSIFICATION[[#This Row],[Functional Scope Aggr]],",",CLASSIFICATION[[#This Row],[Keyword]]) -> Design,UI model,+Business Data Types | J31: =_xlfn.CONCAT(CLASSIFICATION[[#This Row],[Project Stage Aggr]],",",CLASSIFICATION[[#This Row],[Functional Scope Aggr]],",",CLASSIFICATION[[#This Row],[Keyword Aggr]]) -> Design,UI model,+Business Data Types | K31: =_xlfn.CONCAT(CLASSIFICATION[[#This Row],[Project Stage Aggr]],",",CLASSIFICATION[[#This Row],[Functional Scope Aggr]],",",CLASSIFICATION[[#This Row],[Keyword Aggr]],",",CLASSIFICATION[[#This Row],[Importance]]) -> Design,UI model,+Business Data Types,5
C32: +Screen Templates | D32: +Screen Templates | E32: 4 | F32: {=_xlfn.XLOOKUP(TRUE,A$2:A32<>"",A$2:A32,,,-1)} -> Design | G32: {=_xlfn.XLOOKUP(TRUE,B$2:B32<>"",B$2:B32,,,-1)} -> UI model | H32: =IF(CLASSIFICATION[[#This Row],[Classification (Generalized keyword)]]="",CLASSIFICATION[[#This Row],[Keyword]],CLASSIFICATION[[#This Row],[Classification (Generalized keyword)]]) -> +Screen Templates | I32: =_xlfn.CONCAT(CLASSIFICATION[[#This Row],[Project Stage Aggr]],",",CLASSIFICATION[[#This Row],[Functional Scope Aggr]],",",CLASSIFICATION[[#This Row],[Keyword]]) -> Design,UI model,+Screen Templates | J32: =_xlfn.CONCAT(CLASSIFICATION[[#This Row],[Project Stage Aggr]],",",CLASSIFICATION[[#This Row],[Functional Scope Aggr]],",",CLASSIFICATION[[#This Row],[Keyword Aggr]]) -> Design,UI model,+Screen Templates | K32: =_xlfn.CONCAT(CLASSIFICATION[[#This Row],[Project Stage Aggr]],",",CLASSIFICATION[[#This Row],[Functional Scope Aggr]],",",CLASSIFICATION[[#This Row],[Keyword Aggr]],",",CLASSIFICATION[[#This Row],[Importance]]) -> Design,UI model,+Screen Templates,4
C33: +Screen Templates / Sample Power Apps | D33: +Screen Templates | E33: 4 | F33: {=_xlfn.XLOOKUP(TRUE,A$2:A33<>"",A$2:A33,,,-1)} -> Design | G33: {=_xlfn.XLOOKUP(TRUE,B$2:B33<>"",B$2:B33,,,-1)} -> UI model | H33: =IF(CLASSIFICATION[[#This Row],[Classification (Generalized keyword)]]="",CLASSIFICATION[[#This Row],[Keyword]],CLASSIFICATION[[#This Row],[Classification (Generalized keyword)]]) -> +Screen Templates | I33: =_xlfn.CONCAT(CLASSIFICATION[[#This Row],[Project Stage Aggr]],",",CLASSIFICATION[[#This Row],[Functional Scope Aggr]],",",CLASSIFICATION[[#This Row],[Keyword]]) -> Design,UI model,+Screen Templates / Sample Power Apps | J33: =_xlfn.CONCAT(CLASSIFICATION[[#This Row],[Project Stage Aggr]],",",CLASSIFICATION[[#This Row],[Functional Scope Aggr]],",",CLASSIFICATION[[#This Row],[Keyword Aggr]]) -> Design,UI model,+Screen Templates | K33: =_xlfn.CONCAT(CLASSIFICATION[[#This Row],[Project Stage Aggr]],",",CLASSIFICATION[[#This Row],[Functional Scope Aggr]],",",CLASSIFICATION[[#This Row],[Keyword Aggr]],",",CLASSIFICATION[[#This Row],[Importance]]) -> Design,UI model,+Screen Templates,4
C34: +Screen templates / Zoho - Pre-built Apps | D34: +Screen Templates | E34: 4 | F34: {=_xlfn.XLOOKUP(TRUE,A$2:A34<>"",A$2:A34,,,-1)} -> Design | G34: {=_xlfn.XLOOKUP(TRUE,B$2:B34<>"",B$2:B34,,,-1)} -> UI model | H34: =IF(CLASSIFICATION[[#This Row],[Classification (Generalized keyword)]]="",CLASSIFICATION[[#This Row],[Keyword]],CLASSIFICATION[[#This Row],[Classification (Generalized keyword)]]) -> +Screen Templates | I34: =_xlfn.CONCAT(CLASSIFICATION[[#This Row],[Project Stage Aggr]],",",CLASSIFICATION[[#This Row],[Functional Scope Aggr]],",",CLASSIFICATION[[#This Row],[Keyword]]) -> Design,UI model,+Screen templates / Zoho - Pre-built Apps | J34: =_xlfn.CONCAT(CLASSIFICATION[[#This Row],[Project Stage Aggr]],",",CLASSIFICATION[[#This Row],[Functional Scope Aggr]],",",CLASSIFICATION[[#This Row],[Keyword Aggr]]) -> Design,UI model,+Screen Templates | K34: =_xlfn.CONCAT(CLASSIFICATION[[#This Row],[Project Stage Aggr]],",",CLASSIFICATION[[#This Row],[Functional Scope Aggr]],",",CLASSIFICATION[[#This Row],[Keyword Aggr]],",",CLASSIFICATION[[#This Row],[Importance]]) -> Design,UI model,+Screen Templates,4
C35: +UI Branding (no HTML/CSS) | D35: +UI Branding | E35: 3 | F35: {=_xlfn.XLOOKUP(TRUE,A$2:A35<>"",A$2:A35,,,-1)} -> Design | G35: {=_xlfn.XLOOKUP(TRUE,B$2:B35<>"",B$2:B35,,,-1)} -> UI model | H35: =IF(CLASSIFICATION[[#This Row],[Classification (Generalized keyword)]]="",CLASSIFICATION[[#This Row],[Keyword]],CLASSIFICATION[[#This Row],[Classification (Generalized keyword)]]) -> +UI Branding | I35: =_xlfn.CONCAT(CLASSIFICATION[[#This Row],[Project Stage Aggr]],",",CLASSIFICATION[[#This Row],[Functional Scope Aggr]],",",CLASSIFICATION[[#This Row],[Keyword]]) -> Design,UI model,+UI Branding (no HTML/CSS) | J35: =_xlfn.CONCAT(CLASSIFICATION[[#This Row],[Project Stage Aggr]],",",CLASSIFICATION[[#This Row],[Functional Scope Aggr]],",",CLASSIFICATION[[#This Row],[Keyword Aggr]]) -> Design,UI model,+UI Branding | K35: =_xlfn.CONCAT(CLASSIFICATION[[#This Row],[Project Stage Aggr]],",",CLASSIFICATION[[#This Row],[Functional Scope Aggr]],",",CLASSIFICATION[[#This Row],[Keyword Aggr]],",",CLASSIFICATION[[#This Row],[Importance]]) -> Design,UI model,+UI Branding,3
C36: +View Types | E36: 4 | F36: {=_xlfn.XLOOKUP(TRUE,A$2:A36<>"",A$2:A36,,,-1)} -> Design | G36: {=_xlfn.XLOOKUP(TRUE,B$2:B36<>"",B$2:B36,,,-1)} -> UI model | H36: =IF(CLASSIFICATION[[#This Row],[Classification (Generalized keyword)]]="",CLASSIFICATION[[#This Row],[Keyword]],CLASSIFICATION[[#This Row],[Classification (Generalized keyword)]]) -> +View Types | I36: =_xlfn.CONCAT(CLASSIFICATION[[#This Row],[Project Stage Aggr]],",",CLASSIFICATION[[#This Row],[Functional Scope Aggr]],",",CLASSIFICATION[[#This Row],[Keyword]]) -> Design,UI model,+View Types | J36: =_xlfn.CONCAT(CLASSIFICATION[[#This Row],[Project Stage Aggr]],",",CLASSIFICATION[[#This Row],[Functional Scope Aggr]],",",CLASSIFICATION[[#This Row],[Keyword Aggr]]) -> Design,UI model,+View Types | K36: =_xlfn.CONCAT(CLASSIFICATION[[#This Row],[Project Stage Aggr]],",",CLASSIFICATION[[#This Row],[Functional Scope Aggr]],",",CLASSIFICATION[[#This Row],[Keyword Aggr]],",",CLASSIFICATION[[#This Row],[Importance]]) -> Design,UI model,+View Types,4
C37: Boolean Expressions | D37: Expressions | E37: -1 | F37: {=_xlfn.XLOOKUP(TRUE,A$2:A37<>"",A$2:A37,,,-1)} -> Design | G37: {=_xlfn.XLOOKUP(TRUE,B$2:B37<>"",B$2:B37,,,-1)} -> UI model | H37: =IF(CLASSIFICATION[[#This Row],[Classification (Generalized keyword)]]="",CLASSIFICATION[[#This Row],[Keyword]],CLASSIFICATION[[#This Row],[Classification (Generalized keyword)]]) -> Expressions | I37: =_xlfn.CONCAT(CLASSIFICATION[[#This Row],[Project Stage Aggr]],",",CLASSIFICATION[[#This Row],[Functional Scope Aggr]],",",CLASSIFICATION[[#This Row],[Keyword]]) -> Design,UI model,Boolean Expressions | J37: =_xlfn.CONCAT(CLASSIFICATION[[#This Row],[Project Stage Aggr]],",",CLASSIFICATION[[#This Row],[Functional Scope Aggr]],",",CLASSIFICATION[[#This Row],[Keyword Aggr]]) -> Design,UI model,Expressions | K37: =_xlfn.CONCAT(CLASSIFICATION[[#This Row],[Project Stage Aggr]],",",CLASSIFICATION[[#This Row],[Functional Scope Aggr]],",",CLASSIFICATION[[#This Row],[Keyword Aggr]],",",CLASSIFICATION[[#This Row],[Importance]]) -> Design,UI model,Expressions,-1
C38: Conditional Expressions | D38: Expressions | E38: -1 | F38: {=_xlfn.XLOOKUP(TRUE,A$2:A38<>"",A$2:A38,,,-1)} -> Design | G38: {=_xlfn.XLOOKUP(TRUE,B$2:B38<>"",B$2:B38,,,-1)} -> UI model | H38: =IF(CLASSIFICATION[[#This Row],[Classification (Generalized keyword)]]="",CLASSIFICATION[[#This Row],[Keyword]],CLASSIFICATION[[#This Row],[Classification (Generalized keyword)]]) -> Expressions | I38: =_xlfn.CONCAT(CLASSIFICATION[[#This Row],[Project Stage Aggr]],",",CLASSIFICATION[[#This Row],[Functional Scope Aggr]],",",CLASSIFICATION[[#This Row],[Keyword]]) -> Design,UI model,Conditional Expressions | J38: =_xlfn.CONCAT(CLASSIFICATION[[#This Row],[Project Stage Aggr]],",",CLASSIFICATION[[#This Row],[Functional Scope Aggr]],",",CLASSIFICATION[[#This Row],[Keyword Aggr]]) -> Design,UI model,Expressions | K38: =_xlfn.CONCAT(CLASSIFICATION[[#This Row],[Project Stage Aggr]],",",CLASSIFICATION[[#This Row],[Functional Scope Aggr]],",",CLASSIFICATION[[#This Row],[Keyword Aggr]],",",CLASSIFICATION[[#This Row],[Importance]]) -> Design,UI model,Expressions,-1
C39: Data Types | D39: IT Data Types | E39: -4 | F39: {=_xlfn.XLOOKUP(TRUE,A$2:A39<>"",A$2:A39,,,-1)} -> Design | G39: {=_xlfn.XLOOKUP(TRUE,B$2:B39<>"",B$2:B39,,,-1)} -> UI model | H39: =IF(CLASSIFICATION[[#This Row],[Classification (Generalized keyword)]]="",CLASSIFICATION[[#This Row],[Keyword]],CLASSIFICATION[[#This Row],[Classification (Generalized keyword)]]) -> IT Data Types | I39: =_xlfn.CONCAT(CLASSIFICATION[[#This Row],[Project Stage Aggr]],",",CLASSIFICATION[[#This Row],[Functional Scope Aggr]],",",CLASSIFICATION[[#This Row],[Keyword]]) -> Design,UI model,Data Types | J39: =_xlfn.CONCAT(CLASSIFICATION[[#This Row],[Project Stage Aggr]],",",CLASSIFICATION[[#This Row],[Functional Scope Aggr]],",",CLASSIFICATION[[#This Row],[Keyword Aggr]]) -> Design,UI model,IT Data Types | K39: =_xlfn.CONCAT(CLASSIFICATION[[#This Row],[Project Stage Aggr]],",",CLASSIFICATION[[#This Row],[Functional Scope Aggr]],",",CLASSIFICATION[[#This Row],[Keyword Aggr]],",",CLASSIFICATION[[#This Row],[Importance]]) -> Design,UI model,IT Data Types,-4
C40: Expressions | D40: Expressions | E40: -1 | F40: {=_xlfn.XLOOKUP(TRUE,A$2:A40<>"",A$2:A40,,,-1)} -> Design | G40: {=_xlfn.XLOOKUP(TRUE,B$2:B40<>"",B$2:B40,,,-1)} -> UI model | H40: =IF(CLASSIFICATION[[#This Row],[Classification (Generalized keyword)]]="",CLASSIFICATION[[#This Row],[Keyword]],CLASSIFICATION[[#This Row],[Classification (Generalized keyword)]]) -> Expressions | I40: =_xlfn.CONCAT(CLASSIFICATION[[#This Row],[Project Stage Aggr]],",",CLASSIFICATION[[#This Row],[Functional Scope Aggr]],",",CLASSIFICATION[[#This Row],[Keyword]]) -> Design,UI model,Expressions | J40: =_xlfn.CONCAT(CLASSIFICATION[[#This Row],[Project Stage Aggr]],",",CLASSIFICATION[[#This Row],[Functional Scope Aggr]],",",CLASSIFICATION[[#This Row],[Keyword Aggr]]) -> Design,UI model,Expressions | K40: =_xlfn.CONCAT(CLASSIFICATION[[#This Row],[Project Stage Aggr]],",",CLASSIFICATION[[#This Row],[Functional Scope Aggr]],",",CLASSIFICATION[[#This Row],[Keyword Aggr]],",",CLASSIFICATION[[#This Row],[Importance]]) -> Design,UI model,Expressions,-1
...

Sheet TABELA
B1: | | C1: Design | H1: | | I1: Development | P1: | | Q1: Implementation | V1: |
B2: | | C2: Workflow model | D2: Database model | E2: UI model | F2: Validations | G2: Application logic | H2: | | I2: Workflow design and development | J2: Database design | K2: Fetching data | L2: GUI design and development | M2: Data validation development | N2: Actions design and development | O2: Programming | P2: | | Q2: Runtime server installation | R2: Database installation | S2: Client module installation | T2: Deployment | U2: Version control | V2: |
A3: Mendix | B3: | | C3: {=_xlfn.TOCOL(_xlfn.TEXTSPLIT(SUBSTITUTE(VLOOKUP(C$2,INDIRECT("'Platform review'!$C"&_xlfn.XMATCH($A3,'Platform review'!$A$1:$A$127)&":$E"&_xlfn.XMATCH($A3,'Platform review'!$A$1:$A$127)+19),3,FALSE),CHAR(34),""),", "))} -> +BPMN Process Model | D3: {=_xlfn.TOCOL(_xlfn.TEXTSPLIT(SUBSTITUTE(VLOOKUP(D$2,INDIRECT("'Platform review'!$C"&_xlfn.XMATCH($A3,'Platform review'!$A$1:$A$127)&":$E"&_xlfn.XMATCH($A3,'Platform review'!$A$1:$A$127)+19),3,FALSE),CHAR(34),""),", "))} -> Domain Model | E3: {=_xlfn.TOCOL(_xlfn.TEXTSPLIT(SUBSTITUTE(VLOOKUP(E$2,INDIRECT("'Platform review'!$C"&_xlfn.XMATCH($A3,'Platform review'!$A$1:$A$127)&":$E"&_xlfn.XMATCH($A3,'Platform review'!$A$1:$A$127)+19),3,FALSE),CHAR(34),""),", "))} -> Boolean Expressions | F3: {=_xlfn.TOCOL(_xlfn.TEXTSPLIT(SUBSTITUTE(VLOOKUP(F$2,INDIRECT("'Platform review'!$C"&_xlfn.XMATCH($A3,'Platform review'!$A$1:$A$127)&":$E"&_xlfn.XMATCH($A3,'Platform review'!$A$1:$A$127)+19),3,FALSE),CHAR(34),""),", "))} -> Transactions | G3: {=_xlfn.TOCOL(_xlfn.TEXTSPLIT(SUBSTITUTE(VLOOKUP(G$2,INDIRECT("'Platform review'!$C"&_xlfn.XMATCH($A3,'Platform review'!$A$1:$A$127)&":$E"&_xlfn.XMATCH($A3,'Platform review'!$A$1:$A$127)+19),3,FALSE),CHAR(34),""),", "))} -> Sequence Flow | H3: | | I3: {=_xlfn.TOCOL(_xlfn.TEXTSPLIT(SUBSTITUTE(VLOOKUP(I$2,INDIRECT("'Platform review'!$C"&_xlfn.XMATCH($A3,'Platform review'!$A$1:$A$127)&":$E"&_xlfn.XMATCH($A3,'Platform review'!$A$1:$A$127)+19),3,FALSE),CHAR(34),""),", "))} -> +BPMN Process Model | J3: {=_xlfn.TOCOL(_xlfn.TEXTSPLIT(SUBSTITUTE(VLOOKUP(J$2,INDIRECT("'Platform review'!$C"&_xlfn.XMATCH($A3,'Platform review'!$A$1:$A$127)&":$E"&_xlfn.XMATCH($A3,'Platform review'!$A$1:$A$127)+19),3,FALSE),CHAR(34),""),", "))} -> Denormalization | K3: {=_xlfn.TOCOL(_xlfn.TEXTSPLIT(SUBSTITUTE(VLOOKUP(K$2,INDIRECT("'Platform review'!$C"&_xlfn.XMATCH($A3,'Platform review'!$A$1:$A$127)&":$E"&_xlfn.XMATCH($A3,'Platform review'!$A$1:$A$127)+19),3,FALSE),CHAR(34),""),", "))} -> Xpath | L3: {=_xlfn.TOCOL(_xlfn.TEXTSPLIT(SUBSTITUTE(VLOOKUP(L$2,INDIRECT("'Platform review'!$C"&_xlfn.XMATCH($A3,'Platform review'!$A$1:$A$127)&":$E"&_xlfn.XMATCH($A3,'Platform review'!$A$1:$A$127)+19),3,FALSE),CHAR(34),""),", "))} -> HTML | M3: {=_xlfn.TOCOL(_xlfn.TEXTSPLIT(SUBSTITUTE(VLOOKUP(M$2,INDIRECT("'Platform review'!$C"&_xlfn.XMATCH($A3,'Platform review'!$A$1:$A$127)&":$E"&_xlfn.XMATCH($A3,'Platform review'!$A$1:$A$127)+19),3,FALSE),CHAR(34),""),", "))} -> Conditional Expressions | N3: {=_xlfn.TOCOL(_xlfn.TEXTSPLIT(SUBSTITUTE(VLOOKUP(N$2,INDIRECT("'Platform review'!$C"&_xlfn.XMATCH($A3,'Platform review'!$A$1:$A$127)&":$E"&_xlfn.XMATCH($A3,'Platform review'!$A$1:$A$127)+19),3,FALSE),CHAR(34),""),", "))} -> Java | O3: {=_xlfn.TOCOL(_xlfn.TEXTSPLIT(SUBSTITUTE(VLOOKUP(O$2,INDIRECT("'Platform review'!$C"&_xlfn.XMATCH($A3,'Platform review'!$A$1:$A$127)&":$E"&_xlfn.XMATCH($A3,'Platform review'!$A$1:$A$127)+19),3,FALSE),CHAR(34),""),", "))} -> Eclipse | P3: | | Q3: {=_xlfn.TOCOL(_xlfn.TEXTSPLIT(SUBSTITUTE(VLOOKUP(Q$2,INDIRECT("'Platform review'!$C"&_xlfn.XMATCH($A3,'Platform review'!$A$1:$A$127)&":$E"&_xlfn.XMATCH($A3,'Platform review'!$A$1:$A$127)+19),3,FALSE),CHAR(34),""),", "))} -> File Storage | R3: {=_xlfn.TOCOL(_xlfn.TEXTSPLIT(SUBSTITUTE(VLOOKUP(R$2,INDIRECT("'Platform review'!$C"&_xlfn.XMATCH($A3,'Platform review'!$A$1:$A$127)&":$E"&_xlfn.XMATCH($A3,'Platform review'!$A$1:$A$127)+19),3,FALSE),CHAR(34),""),", "))} -> Relational Database | S3: {=_xlfn.TOCOL(_xlfn.TEXTSPLIT(SUBSTITUTE(VLOOKUP(S$2,INDIRECT("'Platform review'!$C"&_xlfn.XMATCH($A3,'Platform review'!$A$1:$A$127)&":$E"&_xlfn.XMATCH($A3,'Platform review'!$A$1:$A$127)+19),3,FALSE),CHAR(34),""),", "))} -> HTTPS Server | T3: {=_xlfn.TOCOL(_xlfn.TEXTSPLIT(SUBSTITUTE(VLOOKUP(T$2,INDIRECT("'Platform review'!$C"&_xlfn.XMATCH($A3,'Platform review'!$A$1:$A$127)&":$E"&_xlfn.XMATCH($A3,'Platform review'!$A$1:$A$127)+19),3,FALSE),CHAR(34),""),", "))} -> Cloud Services | U3: {=_xlfn.TOCOL(_xlfn.TEXTSPLIT(SUBSTITUTE(VLOOKUP(U$2,INDIRECT("'Platform review'!$C"&_xlfn.XMATCH($A3,'Platform review'!$A$1:$A$127)&":$E"&_xlfn.XMATCH($A3,'Platform review'!$A$1:$A$127)+19),3,FALSE),CHAR(34),""),", "))} -> Git | V3: |
B4: | | D4: Data Structure | E4: Responsive Web Design | F4: JavaScript | G4: Activity Diagram | H4: | | I4: Events | J4: Relational Database | K4: OQL | L4: CSS | M4: Boolean Expressions | N4: JavaScript | O4: Java API | P4: | | Q4: Database Synchronization | R4: File Storage | S4: API | T4: CI/CD | U4: Code Repository Concept | V4: |
B5: | | D5: Entity Diagrams | E5: Data Types | F5: String Functions | G5: Control Structures | H5: | | I5: Triggers | J5: SQL | K5: SQL | L5: SASS (SCSS) | M5: Domain Model | N5: API | O5: Java | P5: | | Q5: REST API | T5: Docker | V5: |
B6: | | D6: Association | F6: Conditional Expressions | G6: Algorithms | H6: | | I6: Java API | K6: Odata | L6: Themes | O6: Emulators Andoid iOS | P6: | | Q6: SOAP | T6: Kubernetes | V6: |
B7: | | D7: One-to-Many | F7: Arithmetic Expressions | G7: Java | H7: | | O7: PWA | P7: | | Q7: WSDL | V7: |
B8: | | D8: Many-to-Many | F8: Boolean Expressions | G8: JavaScript | H8: | | O8: Native Mobile App | P8: | | Q8: Swagger | V8: |
B9: | | D9: Denormalization | F9: Enumerations | G9: SQL/OQL | H9: | | P9: | | Q9: Relational Database | V9: |
B10: | | D10: XPath | G10: Regular Expressions | H10: | | P10: | | Q10: Xpath | V10: |
B11: | | G11: Variables | H11: | | P11: | | Q11: OQL | V11: |
B12: | | G12: Data Types | H12: | | P12: | | Q12: Java | V12: |
B13: | | H13: | | P13: | | Q13: API | V13: |
B14: | | H14: | | P14: | | Q14: HTTPS Server | V14: |
B15: | | H15: | | P15: | | V15: |
B16: | | H16: | | P16: | | V16: |
B17: | | H17: | | P17: | | V17: |
B18: | | H18: | | P18: | | V18: |
B19: | | H19: | | P19: | | V19: |
B20: | | H20: | | P20: | | V20: |
